<?xml version="1.0"?>
<robot name="quaro-leg" xmlns:xacro="http://ros.org/wiki/xacro">
  <!-- parameter n is the leg number-->
  <xacro:macro name="leg" params="n x y z rpy parent">
    <!-- 0 value in the inertia tensor can cause the robot to crash and
         sets the link to their origin in the world frame.
    -->
    <xacro:property name="zero" value="1"/>
    <!-- first link -->
    <xacro:ax12a name="hip${n}-servo" rpy="0 ${pi} 0" color="red"/>

    <joint name="hip-link${n}" type="fixed">
      <parent link="${parent}"/>
      <child link="hip${n}-servo"/>
      <origin rpy="${rpy}" xyz="${x*scale} ${y*scale} ${z*scale}"/>
    </joint>

    <link name="thigh${n}">
      <visual>
        <geometry>
          <mesh filename="package://quaro_description/meshes/link-hip.stl" scale="${scale} ${scale} ${scale}"/>
        </geometry>
        <material name="red"/>
        <origin rpy="${0} 0 -${pi/2}" xyz="${24.10*scale} -${0*scale} -${0*scale}"/>
      </visual>
      <inertial>
        <mass value="${19.19*gtoKg}" />
        <origin rpy="${pi} 0 ${pi/2}" xyz="${24.10*scale} -${0*scale} -${0*scale}"/>
        <inertia  ixx="${1783.52*scale_mm2*gtoKg}"
                ixy="${zero*scale_mm2*gtoKg}"
                ixz="${zero*scale_mm2*gtoKg}"
                iyy="${6524.07*scale_mm2*gtoKg}"
                iyz="${-170.99*scale_mm2*gtoKg}"
                izz="${6788.11*scale_mm2*gtoKg}" />
      </inertial>
      <collision>
         <geometry>
           <mesh filename="package://quaro_description/meshes/link-hip.stl" scale="${scale} ${scale} ${scale}"/>
         </geometry>
         <origin rpy="${0} 0 -${pi/2}" xyz="${24.10*scale} -${0*scale} -${0*scale}"/>
       </collision>
    </link>

    <joint name="hip${n}" type="revolute">
      <parent link="hip${n}-servo"/>
      <child link="thigh${n}"/>
      <origin rpy="0 0 0" xyz="${0*scale} ${0*scale} ${0*scale}"/>
      <axis xyz="0 0 1"/>
      <limit effort="100000.0" lower="${-pi/3}" upper="${pi/3}" velocity="0.5"/>
    </joint>

    <xacro:ax12a name="knee${n}-servo" rpy="0 0 0" color="blue"/>

    <joint name="knee${n}-link" type="fixed">
      <parent link="thigh${n}"/>
      <child link="knee${n}-servo"/>
      <origin rpy="-${pi/2} ${pi} 0" xyz="${57.35*scale} ${0.07*scale} -${0.5*scale}"/>
    </joint>

    <link name="shin${n}">
      <visual>
        <geometry>
          <mesh filename="package://quaro_description/meshes/link-knee.stl" scale="${scale} ${scale} ${scale}"/>
        </geometry>
        <material name="blue"/>
        <origin rpy="${0} ${pi/2} ${pi/2}" xyz="-${23.63*scale} ${0*scale} ${0.31*scale}"/>
      </visual>
      <inertial>
        <mass value="${20.73*gtoKg}" />
        <origin rpy="${0} ${pi/2} ${pi/2}" xyz="-${23.63*scale} ${0*scale} ${0.31*scale}"/>
        <inertia  ixx="${8962.80*scale_mm2*gtoKg}"
                ixy="${-167.48*scale_mm2*gtoKg}"
                ixz="${zero*scale_mm2*gtoKg}"
                iyy="${6916.45*scale_mm2*gtoKg}"
                iyz="${zero*scale_mm2*gtoKg}"
                izz="${10135.24*scale_mm2*gtoKg}" />
      </inertial>
      <collision>
         <geometry>
           <mesh filename="package://quaro_description/meshes/link-knee.stl" scale="${scale} ${scale} ${scale}"/>
         </geometry>
         <origin rpy="${0} ${pi/2} ${pi/2}" xyz="-${23.63*scale} ${0*scale} ${0.31*scale}"/>
       </collision>
    </link>

    <joint name="knee${n}" type="revolute">
      <parent link="knee${n}-servo"/>
      <child link="shin${n}"/>
      <origin rpy="0 0 0" xyz="${0*scale} 0 0"/>
      <axis xyz="0 0 1"/>
      <limit effort="100000.0" lower="${-pi/3}" upper="${pi/3}" velocity="0.5"/>
    </joint>

    <xacro:ax12a name="ankle${n}-servo" rpy="0 0 0" color="green"/>

    <joint name="ankle${n}-link" type="fixed">
      <parent link="shin${n}"/>
      <child link="ankle${n}-servo"/>
      <origin rpy="${0} ${0} ${0}" xyz="-${58*scale} 0 0"/>
    </joint>

    <link name="foot${n}">
      <visual>
        <geometry>
          <mesh filename="package://quaro_description/meshes/link-foot.stl" scale="${scale} ${scale} ${scale}"/>
        </geometry>
        <material name="green"/>
        <origin rpy="${0} 0 ${0}" xyz="${35.02*scale} -${28.64*scale} ${2.64*scale}"/>
      </visual>
      <inertial>
        <mass value="${27.98*gtoKg}" />
        <origin ryp="0 0 0" xyz="${35.02*scale} -${28.64*scale} ${2.64*scale}"/>

        <inertia  ixx="${44410.23*scale_mm2*gtoKg}"
                ixy="${-22384.35*scale_mm2*gtoKg}"
                ixz="${-249.17*scale_mm2*gtoKg}"
                iyy="${20692.66*scale_mm2*gtoKg}"
                iyz="${202.94*scale_mm2*gtoKg}"
                izz="${55471.08*scale_mm2*gtoKg}" />
      </inertial>
      <collision>
         <geometry>
           <mesh filename="package://quaro_description/meshes/link-foot.stl" scale="${scale} ${scale} ${scale}"/>
         </geometry>
           <origin rpy="${0} 0 ${0}" xyz="${35.02*scale} -${28.64*scale} ${2.64*scale}"/>
       </collision>
    </link>

    <joint name="ankle${n}" type="revolute">
      <parent link="ankle${n}-servo"/>
      <child link="foot${n}"/>
      <origin rpy="0 ${pi} 0" xyz="${0*scale} 0 0"/>
      <axis xyz="0 0 1"/>
      <limit effort="100000.0" lower="${-pi/3}" upper="${pi/3}" velocity="0.5"/>
    </joint>

  </xacro:macro>
</robot>
