<?xml version="1.0"?>
<robot name="quaro-body" xmlns:xacro="http://ros.org/wiki/xacro">
  <!-- Sensor param will be used later when stereo camera and other sensors will be installed. -->
  <xacro:macro name="body" params="sensors">

  <link name="back">
    <visual>
      <geometry>
        <mesh filename="package://quaro_description/meshes/back.stl" scale="${scale} ${scale} ${scale}"/>
      </geometry>
      <material name="gray"/>
      <origin rpy="0 0 0" xyz="${0*scale} 0 ${0*scale}"/>
    </visual>
    <inertial>
      <mass value="${60*gtoKg}" />
      <origin rpy="0 0 0" xyz="-${54.98*scale} ${0*scale} -${21.33*scale}"/>
      <inertia  ixx="${1*scale_mm2*gtoKg}"
                ixy="${0*scale_mm2*gtoKg}"
                ixz="${0*scale_mm2*gtoKg}"
                iyy="${1*scale_mm2*gtoKg}"
                iyz="${0*scale_mm2*gtoKg}"
                izz="${1*scale_mm2*gtoKg}" />
    </inertial>
    <collision>
       <geometry>
         <mesh filename="package://quaro_description/meshes/back.stl" scale="${scale} ${scale} ${scale}"/>
       </geometry>
       <origin rpy="0 0 0" xyz="${0*scale} 0 ${0*scale}"/>
    </collision>
  </link>

  <link name="chest-servo">
    <visual>
      <geometry>
        <mesh filename="package://quaro_description/meshes/AX-12A.stl" scale="${scale} ${scale} ${scale}"/>
      </geometry>
      <material name="red"/>
      <origin rpy="0 0 0" xyz="${0*scale} ${0*scale} ${0*scale}"/>
    </visual>
    <inertial>
      <mass value="${60*gtoKg}" />
      <origin rpy="0 0 0" xyz="${12.61*scale} ${0*scale} ${1.21*scale}"/>
      <inertia  ixx="${1*scale_mm2*gtoKg}"
              ixy="${0*scale_mm2*gtoKg}"
              ixz="${0*scale_mm2*gtoKg}"
              iyy="${1*scale_mm2*gtoKg}"
              iyz="${0*scale_mm2*gtoKg}"
              izz="${1*scale_mm2*gtoKg}" />
    </inertial>
    <collision>
       <geometry>
         <mesh filename="package://quaro_description/meshes/AX-12A.stl" scale="${scale} ${scale} ${scale}"/>
       </geometry>
       <origin rpy="0 0 0" xyz="${0*scale} ${0*scale} ${0*scale}"/>
     </collision>
  </link>

  <link name="spine">
    <visual>
      <geometry>
        <mesh filename="package://quaro_description/meshes/link-chest.stl" scale="${scale} ${scale} ${scale}"/>
      </geometry>
      <material name="yellow"/>
      <origin rpy="0 0 0" xyz="${16.58*scale} -${0.56*scale} ${0*scale}"/>
    </visual>
    <inertial>
      <mass value="${60*gtoKg}" />
      <origin rpy="0 0 0" xyz="${0*scale} -${0.56*scale} ${0*scale}"/>
      <inertia  ixx="${1*scale_mm2*gtoKg}"
                ixy="${0*scale_mm2*gtoKg}"
                ixz="${0*scale_mm2*gtoKg}"
                iyy="${1*scale_mm2*gtoKg}"
                iyz="${0*scale_mm2*gtoKg}"
                izz="${1*scale_mm2*gtoKg}" />
    </inertial>
    <collision>
       <geometry>
         <mesh filename="package://quaro_description/meshes/link-chest.stl" scale="${scale} ${scale} ${scale}"/>
       </geometry>
       <origin rpy="0 0 0" xyz="${16.58*scale} -${0.56*scale} ${0*scale}"/>
     </collision>
  </link>

  <link name="front">
    <visual>
      <geometry>
        <mesh filename="package://quaro_description/meshes/front.stl" scale="${scale} ${scale} ${scale}"/>
      </geometry>
      <material name="pink"/>
      <origin rpy="${0} ${0} ${0}" xyz="${0*scale} ${0*scale} ${0*scale}"/>
    </visual>
    <inertial>
      <mass value="${60*gtoKg}" />
      <origin rpy="0 0 0" xyz="${71.80*scale} ${0*scale} -${24.62*scale}"/>
      <inertia  ixx="${1*scale_mm2*gtoKg}"
                ixy="${0*scale_mm2*gtoKg}"
                ixz="${0*scale_mm2*gtoKg}"
                iyy="${1*scale_mm2*gtoKg}"
                iyz="${0*scale_mm2*gtoKg}"
                izz="${1*scale_mm2*gtoKg}" />
    </inertial>
    <collision>
       <geometry>
         <mesh filename="package://quaro_description/meshes/front.stl" scale="${scale} ${scale} ${scale}"/>
       </geometry>
       <origin rpy="0 0 0" xyz="0 0 ${0*scale}"/>
     </collision>
  </link>

  <joint name="servo-link" type="fixed">
    <parent link="back"/>
    <child link="chest-servo"/>
    <origin rpy="${pi/2} ${pi} 0" xyz="${0*scale} -${0.17*scale} -${21*scale}"/>
  </joint>

  <joint name="chest" type="revolute">
    <parent link="chest-servo"/>
    <child link="spine"/>
    <origin rpy="${-pi/2} ${0} ${-pi}" xyz="-${0*scale} -${0*scale} ${0*scale}"/>
    <axis xyz="0 1 0"/>
    <limit effort="1000.0" lower="${-pi/2}" upper="${pi/2}" velocity="0.5"/>
  </joint>

  <joint name="last" type="fixed">
    <parent link="spine"/>
    <child link="front"/>
    <origin ryp="${0} ${0} ${0}" xyz="${16.58*scale} ${0*scale} ${21*scale}"/>
  </joint>

  </xacro:macro>
</robot>
